Workbook

Sheet Entrada
A3: cálculo baseado no orçamento
A4: Orçamento Total (€) | B4: 50000 | H4: cálculo baseado nos convidados
A5: Nº de Convidados | B5: 100 | H5: Nº de Convidados | I5: 500
A6: Distrito | B6: Aveiro | H6: tipo de cerimonia | I6: Registo Civil - Externo
A7: Época do ano | H7: Estilo | I7: Platinum
A8: tipo de cerimonia | H8: Distrito | I8: Lisboa
H9: Época do ano
H11: Total | I11: ='Parâmetros'!K23 -> 134400
H12: orçamento por estilo

Sheet Parâmetros
A1: Categoria | B1: Distrito | C1: Estilo | D1: Valor | E1: TipoValor
A2: Espaços | B2: Aveiro | C2: Smart | D2: =AVERAGE('Espaços'!E3:E7) -> 32 | E2: PP | H2: cálculo baseado nos convidados
A3: Espaços | B3: Aveiro | C3: Select | D3: =AVERAGE('Espaços'!E8:E32) -> 52.76 | E3: PP | H3: Categoria | I3: Qtde | J3: Preço unitário (€) | K3: Total (€)
A4: Espaços | B4: Aveiro | C4: Premium | D4: =AVERAGE('Espaços'!E33:E59) -> 87.833333 | E4: PP | H4: Espaços | I4: =Entrada!I5 -> 500 | J4: =IFERROR(__xludf.DUMMYFUNCTION("INDEX(VALUE(SUBSTITUTE(FILTER('Parâmetros'!$D$2:D1041, 'Parâmetros'!$A$2:A1041=""Espaços"", 'Parâmetros'!$B$2:B1041=Entrada!$I$8, 'Parâmetros'!$C$2:C1041=Entrada!$I$7), "" €"","""")), 1)"),151.0) -> 151 | K4: =I4*J4 -> 75500
A5: Espaços | B5: Aveiro | C5: Platinum | D5: =AVERAGE('Espaços'!E60:E65) -> 162.5 | E5: PP | H5: Fotografia | I5: 1 | J5: =IFERROR(__xludf.DUMMYFUNCTION("INDEX(VALUE(SUBSTITUTE(FILTER('Parâmetros'!$D$2:D1041, 'Parâmetros'!$A$2:A1041=""Fotografia"", 'Parâmetros'!$B$2:B1041=Entrada!$I$8, 'Parâmetros'!$C$2:C1041=Entrada!$I$7), "" €"","""")), 1)"),4500.0) -> 4500 | K5: =I5*J5 -> 4500
A6: Espaços | B6: Beja | C6: Smart | D6: 28.58 | E6: PP | H6: Vídeo | I6: 1 | J6: =IFERROR(__xludf.DUMMYFUNCTION("INDEX(VALUE(SUBSTITUTE(FILTER('Parâmetros'!$D$2:D1041, 'Parâmetros'!$A$2:A1041=""Vídeo"", 'Parâmetros'!$B$2:B1041=Entrada!$I$8, 'Parâmetros'!$C$2:C1041=Entrada!$I$7), "" €"","""")), 1)"),5000.0) -> 5000 | K6: =I6*J6 -> 5000
A7: Espaços | B7: Beja | C7: Select | D7: 57.93 | E7: PP | H7: Música & Animação | I7: 1 | J7: =IFERROR(__xludf.DUMMYFUNCTION("INDEX(VALUE(SUBSTITUTE(FILTER('Parâmetros'!$D$2:D1041, 'Parâmetros'!$A$2:A1041=""Música & Animação"", 'Parâmetros'!$B$2:B1041=Entrada!$I$8, 'Parâmetros'!$C$2:C1041=Entrada!$I$7), "" €"","""")), 1)"),3500.0) -> 3500 | K7: =I7*J7 -> 3500
A8: Espaços | B8: Beja | C8: Premium | D8: 85.56 | E8: PP | H8: Decoração & Flores | I8: 1 | J8: =IFERROR(__xludf.DUMMYFUNCTION("INDEX(VALUE(SUBSTITUTE(FILTER('Parâmetros'!$D$2:D1041, 'Parâmetros'!$A$2:A1041=""Decoração & Flores"", 'Parâmetros'!$B$2:B1041=Entrada!$I$8, 'Parâmetros'!$C$2:C1041=Entrada!$I$7), "" €"","""")), 1)"),8000.0) -> 8000 | K8: =I8*J8 -> 8000
A9: Espaços | B9: Beja | C9: Platinum | D9: 150.89 | E9: PP | H9: Noiva | I9: 1 | J9: =IFERROR(__xludf.DUMMYFUNCTION("INDEX(VALUE(SUBSTITUTE(FILTER('Parâmetros'!$D$2:D1041, 'Parâmetros'!$A$2:A1041=""Noiva"", 'Parâmetros'!$B$2:B1041=Entrada!$I$8, 'Parâmetros'!$C$2:C1041=Entrada!$I$7), "" €"","""")), 1)"),3500.0) -> 3500 | K9: =I9*J9 -> 3500
A10: Espaços | B10: Braga | C10: Smart | D10: =AVERAGE('Espaços'!E69:E70) -> 25.5 | E10: PP | H10: Noivo | I10: 1 | J10: =IFERROR(__xludf.DUMMYFUNCTION("INDEX(VALUE(SUBSTITUTE(FILTER('Parâmetros'!$D$2:D1041, 'Parâmetros'!$A$2:A1041=""Noivo"", 'Parâmetros'!$B$2:B1041=Entrada!$I$8, 'Parâmetros'!$C$2:C1041=Entrada!$I$7), "" €"","""")), 1)"),3000.0) -> 3000 | K10: =I10*J10 -> 3000
A11: Espaços | B11: Braga | C11: Select | D11: =AVERAGE('Espaços'!E71:E106) -> 56.055556 | E11: PP | H11: Convites | I11: =Entrada!I5 -> 500 | J11: =IFERROR(__xludf.DUMMYFUNCTION("INDEX(VALUE(SUBSTITUTE(FILTER('Parâmetros'!$D$2:D1041, 'Parâmetros'!$A$2:A1041=""Convites"", 'Parâmetros'!$B$2:B1041=Entrada!$I$8, 'Parâmetros'!$C$2:C1041=Entrada!$I$7), "" €"","""")), 1)"),40.0) -> 40 | K11: =I11*J11 -> 20000
A12: Espaços | B12: Braga | C12: Premium | D12: =AVERAGE('Espaços'!E107:E157) -> 86.235294 | E12: PP | H12: Lembranças | I12: =Entrada!I5 -> 500 | J12: =IFERROR(__xludf.DUMMYFUNCTION("INDEX(VALUE(SUBSTITUTE(FILTER('Parâmetros'!$D$2:D1041, 'Parâmetros'!$A$2:A1041=""Lembranças"", 'Parâmetros'!$B$2:B1041=Entrada!$I$8, 'Parâmetros'!$C$2:C1041=Entrada!$I$7), "" €"","""")), 1)"),20.0) -> 20 | K12: =I12*J12 -> 10000
A13: Espaços | B13: Braga | C13: Platinum | D13: =AVERAGE('Espaços'!E158:E170) -> 188.76923 | E13: PP | H13: Transporte | I13: 1 | J13: =IFERROR(__xludf.DUMMYFUNCTION("INDEX(VALUE(SUBSTITUTE(FILTER('Parâmetros'!$D$2:D1041, 'Parâmetros'!$A$2:A1041=""Transporte"", 'Parâmetros'!$B$2:B1041=Entrada!$I$8, 'Parâmetros'!$C$2:C1041=Entrada!$I$7), "" €"","""")), 1)"),1200.0) -> 1200 | K13: =I13*J13 -> 1200
A14: Espaços | B14: Bragança | C14: Smart | D14: 28.58 | E14: PP
A15: Espaços | B15: Bragança | C15: Select | D15: =AVERAGE('Espaços'!E172:E174) -> 70 | E15: PP | H15: sub total | K15: =SUM(K4:K13) -> 134200
A16: Espaços | B16: Bragança | C16: Premium | D16: =AVERAGE('Espaços'!E175:E183) -> 95.444444 | E16: PP
A17: Espaços | B17: Bragança | C17: Platinum | D17: 150.89 | E17: PP | H17: Registo Civil - Cartório | I17: 1 | J17: =IFERROR(__xludf.DUMMYFUNCTION("INDEX(VALUE(SUBSTITUTE(FILTER('Parâmetros'!$D$2:D1041, 'Parâmetros'!$A$2:A1041=""Registo Civil - Cartório"", 'Parâmetros'!$B$2:B1041=Entrada!$I$8, 'Parâmetros'!$C$2:C1041=Entrada!$I$7), "" €"","""")), 1)"),120.0) -> 120 | K17: =I17*J17 -> 120
A18: Espaços | B18: Castelo Branco | C18: Smart | D18: =AVERAGE('Espaços'!E186:E187) -> 26.5 | E18: PP | H18: Registo Civil - Externo | I18: 1 | J18: =IFERROR(__xludf.DUMMYFUNCTION("INDEX(VALUE(SUBSTITUTE(FILTER('Parâmetros'!$D$2:D1041, 'Parâmetros'!$A$2:A1041=""Registo Civil - Externo"", 'Parâmetros'!$B$2:B1041=Entrada!$I$8, 'Parâmetros'!$C$2:C1041=Entrada!$I$7), "" €"","""")), 1)"),200.0) -> 200 | K18: =I18*J18 -> 200
A19: Espaços | B19: Castelo Branco | C19: Select | D19: =AVERAGE('Espaços'!E188:E199) -> 52.083333 | E19: PP | H19: Igreja | I19: 1 | J19: =IFERROR(__xludf.DUMMYFUNCTION("INDEX(VALUE(SUBSTITUTE(FILTER('Parâmetros'!$D$2:D1041, 'Parâmetros'!$A$2:A1041=""Igreja"", 'Parâmetros'!$B$2:B1041=Entrada!$I$8, 'Parâmetros'!$C$2:C1041=Entrada!$I$7), "" €"","""")), 1)"),200.0) -> 200 | K19: =I19*J19 -> 200
A20: Espaços | B20: Castelo Branco | C20: Premium | D20: =AVERAGE('Espaços'!E200:E212) -> 82.115385 | E20: PP
A21: Espaços | B21: Castelo Branco | C21: Platinum | D21: 150.89 | E21: PP | H21: sub total | K21: =SWITCH(TRIM(Entrada!$I$6),"Registo Civil - Externo",SUMIF($H$17:$H$19, "Registo Civil - Externo", $K$17:$K$19),"Igreja",SUMIF($H$17:$H$19, "Registo Civil - Cartório", $K$17:$K$19)+SUMIF($H$17:$H$19, "Igreja", $K$17:$K$19),"Registo Civil - Cartório",SUMIF($H$17:$H$19, "Registo Civil - Cartório", $K$17:$K$19), 0) -> 200
A22: Espaços | B22: Coimbra | C22: Smart | D22: =AVERAGE('Espaços'!E213:E219) -> 28.5 | E22: PP
A23: Espaços | B23: Coimbra | C23: Select | D23: =AVERAGE('Espaços'!E220:E241) -> 54.904545 | E23: PP | H23: Total | K23: =SUM(K15,K21) -> 134400
A24: Espaços | B24: Coimbra | C24: Premium | D24: =AVERAGE('Espaços'!E242:E253) -> 83.083333 | E24: PP
A25: Espaços | B25: Coimbra | C25: Platinum | D25: =AVERAGE('Espaços'!E254:E257) -> 120 | E25: PP
A26: Espaços | B26: Évora | C26: Smart | D26: =AVERAGE('Espaços'!E258:E261) -> 24.75 | E26: PP
A27: Espaços | B27: Évora | C27: Select | D27: =AVERAGE('Espaços'!E262:E269) -> 62.75 | E27: PP
A28: Espaços | B28: Évora | C28: Premium | D28: =AVERAGE('Espaços'!E270:E280) -> 80.727273 | E28: PP
A29: Espaços | B29: Évora | C29: Platinum | D29: =AVERAGE('Espaços'!E281:E283) -> 113.66667 | E29: PP
A30: Espaços | B30: Faro | C30: Smart | D30: =AVERAGE('Espaços'!E284:E290) -> 24.714286 | E30: PP | H30: cálculo baseado no orçamento
A31: Espaços | B31: Faro | C31: Select | D31: =AVERAGE('Espaços'!E291:E321) -> 57.322581 | E31: PP | H31: Distribuição recomendada do orçamento (ajustável)
A32: Espaços | B32: Faro | C32: Premium | D32: =AVERAGE('Espaços'!E322:E341) -> 88.05 | E32: PP | H32: Categoria | I32: Percentagem (%) | J32: Valor (€) | K32: € pp/total
A33: Espaços | B33: Faro | C33: Platinum | D33: =AVERAGE('Espaços'!E342:E377) -> 159.70833 | E33: PP | H33: Espaços | I33: 50 | J33: =IF(Entrada!$B$4>0, I33*Entrada!$B$4/100, 0) -> 25000 | K33: =J33/Entrada!B5 -> 250
A34: Espaços | B34: Guarda | C34: Smart | D34: 28.58 | E34: PP | H34: Fotografia | I34: 8 | J34: =IF(Entrada!$B$4>0, I34*Entrada!$B$4/100, 0) -> 4000 | K34: =J34 -> 4000
A35: Espaços | B35: Guarda | C35: Select | D35: =AVERAGE('Espaços'!E378:E387) -> 61.5 | E35: PP | H35: Vídeo | I35: 5 | J35: =IF(Entrada!$B$4>0, I35*Entrada!$B$4/100, 0) -> 2500 | K35: =J35 -> 2500
A36: Espaços | B36: Guarda | C36: Premium | D36: =AVERAGE('Espaços'!E388:E392) -> 85 | E36: PP | H36: Música & Animação | I36: 5 | J36: =IF(Entrada!$B$4>0, I36*Entrada!$B$4/100, 0) -> 2500 | K36: =J36 -> 2500
A37: Espaços | B37: Guarda | C37: Platinum | D37: =AVERAGE('Espaços'!E393:E394) -> 115 | E37: PP | H37: Decoração & Flores | I37: 8 | J37: =IF(Entrada!$B$4>0, I37*Entrada!$B$4/100, 0) -> 4000 | K37: =J37 -> 4000
A38: Espaços | B38: Leiria | C38: Smart | D38: =AVERAGE('Espaços'!E395:E402) -> 26.25 | E38: PP | H38: Noiva & Noivo (vestuário) | I38: 11 | J38: =IF(Entrada!$B$4>0, I38*Entrada!$B$4/100, 0) -> 5500 | K38: =J38 -> 5500
A39: Espaços | B39: Leiria | C39: Select | D39: =AVERAGE('Espaços'!E403:E424) -> 55.271818 | E39: PP | H39: Convites | I39: 2 | J39: =IF(Entrada!$B$4>0, I39*Entrada!$B$4/100, 0) -> 1000 | K39: =J39/Entrada!B5 -> 10
A40: Espaços | B40: Leiria | C40: Premium | D40: =AVERAGE('Espaços'!E425:E437) -> 81.423077 | E40: PP | H40: Lembranças | I40: 2 | J40: =IF(Entrada!$B$4>0, I40*Entrada!$B$4/100, 0) -> 1000 | K40: =J40/Entrada!B5 -> 10
...

Sheet Espaços
B2: Distrito | C2: Espaço | D2: Nome | E2: Preço | F2: Estrelas | G2: Nº pessoas | H2: Link
B3: Aveiro | C3: Quintas | D3: Villa Diogo 1906 | E3: 25 | F3: 0 | G3: 250 | H3: Link
B4: Aveiro | C4: Quintas | D4: Teamevents | E4: 30 | F4: 0 | G4: 75 | H4: Link
B5: Aveiro | C5: Quintas | D5: Riabela Eventos | E5: 35 | F5: 4.7 | G5: 350 | H5: Link
B6: Aveiro | C6: Quintas | D6: Solar das Estátuas | E6: 35 | F6: 0 | G6: 400 | H6: Link
B7: Aveiro | C7: Hotéis | D7: Tulip Inn Estarreja Hotel & Spa | E7: 35 | F7: 4.6 | G7: 180 | H7: Link
B8: Aveiro | C8: Quintas | D8: Quinta Sol Nascente | E8: 40 | F8: 4.9 | G8: 300 | H8: Link
B9: Aveiro | C9: Quintas | D9: Quinta dos Vales | E9: 40 | F9: 4.4 | G9: 300 | H9: Link
B10: Aveiro | C10: Quintas | D10: Quinta da Relva | E10: 40 | F10: 4.1 | G10: 300 | H10: Link
B11: Aveiro | C11: Quintas | D11: Dom Rogério Oiã | E11: 40 | F11: 4.9 | G11: 300 | H11: Link
B12: Aveiro | C12: Quintas | D12: Casa dos Maias | E12: 40 | F12: 4.7 | G12: 300 | H12: Link
B13: Aveiro | C13: Hotéis | D13: Hostel da Praça | E13: 40 | F13: 0 | G13: 80 | H13: Link
B14: Aveiro | C14: Quintas | D14: Quinta da Avistada | E14: 45 | F14: 4.5 | G14: 600 | H14: Link
... B1200: Madeira | C1200: Quintas | D1200: Palheiro Nature Estate | E1200: 185 | F1200: 4.9 | G1200: 100 | H1200: Link

Sheet RESUMO_EMAIL
A1: Resumo para e-mail (copiar/colar e personalizar)
A3: Dados Base
A4: Orçamento Total (€) | B4: ='CHECK-UP FINANCEIRO'!C23 -> #REF!
A5: Nº de Convidados | B5: ='CHECK-UP FINANCEIRO'!C24 -> #REF!
A6: € por Convidado (calc.) | B6: =IF('CHECK-UP FINANCEIRO'!C24>0, 'CHECK-UP FINANCEIRO'!C23/'CHECK-UP FINANCEIRO'!C24, 0) -> #REF!
A7: Região | B7: ='CHECK-UP FINANCEIRO'!C25 -> #REF!
A8: Estilo | B8: ='CHECK-UP FINANCEIRO'!#REF! -> #ERROR!
A9: Prioridades | B9: ='CHECK-UP FINANCEIRO'!C27 -> #REF!
A11: Distribuição Recomendada (ajuste livre)
A12: Categoria | B12: % | C12: €
A13: Espaço & Catering | B13: ='Parâmetros'!I33 -> 50 | C13: ='Parâmetros'!J33 -> 25000
A14: Fotografia | B14: ='Parâmetros'!I34 -> 8 | C14: ='Parâmetros'!J34 -> 4000
A15: Vídeo | B15: ='Parâmetros'!I35 -> 5 | C15: ='Parâmetros'!J35 -> 2500
A16: Decoração & Flores | B16: ='Parâmetros'!I37 -> 8 | C16: ='Parâmetros'!J37 -> 4000
A17: Música & Animação | B17: ='Parâmetros'!I36 -> 5 | C17: ='Parâmetros'!J36 -> 2500
A18: Estacionário & Convites | B18: ='Parâmetros'!I39 -> 2 | C18: ='Parâmetros'!J39 -> 1000
A19: Transporte | B19: ='Parâmetros'!I41 -> 2 | C19: ='Parâmetros'!J41 -> 1000
A20: Noiva & Noivo (vestuário) | B20: ='Parâmetros'!I38 -> 11 | C20: ='Parâmetros'!J38 -> 5500
A21: Lembranças & Detalhes | B21: ='Parâmetros'!I40 -> 2 | C21: ='Parâmetros'!J40 -> 1000
A22: Assessoria & Coordenação (opcional) | B22: ='Parâmetros'!I42 -> 2 | C22: ='Parâmetros'!J42 -> 1000
A23: Margem de Imprevistos | B23: ='Parâmetros'!I43 -> 5 | C23: ='Parâmetros'!J43 -> 2500
A24: Totais | B24: =SUM(B13:B23) -> 100 | C24: =SUM(C13:C23) -> 50000
A26: Alertas Rápidos (preencher manualmente)
A27: -
A28: -
A29: -
A30: Próximos Passos Recomendados (preencher manualmente)
A31: -
A32: -
A33: -
